Workbook

Sheet Sheet8
A1: Years | B1: Planterware Profit % | C1: Forecast(Planterware Profit %) | D1: Lower Confidence Bound(Planterware Profit %) | E1: Upper Confidence Bound(Planterware Profit %)
A2: 2006 | B2: 0
A3: 2007 | B3: 0
A4: 2008 | B4: 0
A5: 2009 | B5: 0
A6: 2010 | B6: 0.015657436
A7: 2011 | B7: -0.011998599
A8: 2012 | B8: -0.0086839589 | C8: -0.0086839589 | D8: -0.0086839589 | E8: -0.0086839589
A9: 2013 | C9: =_xlfn.FORECAST.ETS(A9,$B$2:$B$8,$A$2:$A$8,1,1) -> -0.0084742344 | D9: =C9-_xlfn.FORECAST.ETS.CONFINT(A9,$B$2:$B$8,$A$2:$A$8,0.95,1,1) -> -0.024712869 | E9: =C9+_xlfn.FORECAST.ETS.CONFINT(A9,$B$2:$B$8,$A$2:$A$8,0.95,1,1) -> 0.0077644
A10: 2014 | C10: =_xlfn.FORECAST.ETS(A10,$B$2:$B$8,$A$2:$A$8,1,1) -> -0.0096819835 | D10: =C10-_xlfn.FORECAST.ETS.CONFINT(A10,$B$2:$B$8,$A$2:$A$8,0.95,1,1) -> -0.025920691 | E10: =C10+_xlfn.FORECAST.ETS.CONFINT(A10,$B$2:$B$8,$A$2:$A$8,0.95,1,1) -> 0.006556724
A11: 2015 | C11: =_xlfn.FORECAST.ETS(A11,$B$2:$B$8,$A$2:$A$8,1,1) -> -0.010889733 | D11: =C11-_xlfn.FORECAST.ETS.CONFINT(A11,$B$2:$B$8,$A$2:$A$8,0.95,1,1) -> -0.02712857 | E11: =C11+_xlfn.FORECAST.ETS.CONFINT(A11,$B$2:$B$8,$A$2:$A$8,0.95,1,1) -> 0.0053491047
A12: 2016 | C12: =_xlfn.FORECAST.ETS(A12,$B$2:$B$8,$A$2:$A$8,1,1) -> -0.012097482 | D12: =C12-_xlfn.FORECAST.ETS.CONFINT(A12,$B$2:$B$8,$A$2:$A$8,0.95,1,1) -> -0.028336522 | E12: =C12+_xlfn.FORECAST.ETS.CONFINT(A12,$B$2:$B$8,$A$2:$A$8,0.95,1,1) -> 0.0041415586
A13: 2017 | C13: =_xlfn.FORECAST.ETS(A13,$B$2:$B$8,$A$2:$A$8,1,1) -> -0.013305231 | D13: =C13-_xlfn.FORECAST.ETS.CONFINT(A13,$B$2:$B$8,$A$2:$A$8,0.95,1,1) -> -0.029544563 | E13: =C13+_xlfn.FORECAST.ETS.CONFINT(A13,$B$2:$B$8,$A$2:$A$8,0.95,1,1) -> 0.0029341018

Sheet Sheet9
A1: Years | B1: Self Watering Profit % | C1: Forecast(Self Watering Profit %) | D1: Lower Confidence Bound(Self Watering Profit %) | E1: Upper Confidence Bound(Self Watering Profit %)
A2: 2006 | B2: 0.84680475
A3: 2007 | B3: 0.87116813
A4: 2008 | B4: 0.85565081
A5: 2009 | B5: 0.8943359
A6: 2010 | B6: 0.64545676
A7: 2011 | B7: 0.75770816
A8: 2012 | B8: 0.74140511 | C8: 0.74140511 | D8: 0.74140511 | E8: 0.74140511
A9: 2013 | C9: =_xlfn.FORECAST.ETS(A9,$B$2:$B$8,$A$2:$A$8,1,1) -> 0.67772982 | D9: =C9-_xlfn.FORECAST.ETS.CONFINT(A9,$B$2:$B$8,$A$2:$A$8,0.95,1,1) -> 0.53691202 | E9: =C9+_xlfn.FORECAST.ETS.CONFINT(A9,$B$2:$B$8,$A$2:$A$8,0.95,1,1) -> 0.81854763
A10: 2014 | C10: =_xlfn.FORECAST.ETS(A10,$B$2:$B$8,$A$2:$A$8,1,1) -> 0.6510101 | D10: =C10-_xlfn.FORECAST.ETS.CONFINT(A10,$B$2:$B$8,$A$2:$A$8,0.95,1,1) -> 0.50947587 | E10: =C10+_xlfn.FORECAST.ETS.CONFINT(A10,$B$2:$B$8,$A$2:$A$8,0.95,1,1) -> 0.79254432
A11: 2015 | C11: =_xlfn.FORECAST.ETS(A11,$B$2:$B$8,$A$2:$A$8,1,1) -> 0.62429037 | D11: =C11-_xlfn.FORECAST.ETS.CONFINT(A11,$B$2:$B$8,$A$2:$A$8,0.95,1,1) -> 0.48202918 | E11: =C11+_xlfn.FORECAST.ETS.CONFINT(A11,$B$2:$B$8,$A$2:$A$8,0.95,1,1) -> 0.76655155
A12: 2016 | C12: =_xlfn.FORECAST.ETS(A12,$B$2:$B$8,$A$2:$A$8,1,1) -> 0.59757064 | D12: =C12-_xlfn.FORECAST.ETS.CONFINT(A12,$B$2:$B$8,$A$2:$A$8,0.95,1,1) -> 0.45457198 | E12: =C12+_xlfn.FORECAST.ETS.CONFINT(A12,$B$2:$B$8,$A$2:$A$8,0.95,1,1) -> 0.7405693
A13: 2017 | C13: =_xlfn.FORECAST.ETS(A13,$B$2:$B$8,$A$2:$A$8,1,1) -> 0.57085091 | D13: =C13-_xlfn.FORECAST.ETS.CONFINT(A13,$B$2:$B$8,$A$2:$A$8,0.95,1,1) -> 0.42710428 | E13: =C13+_xlfn.FORECAST.ETS.CONFINT(A13,$B$2:$B$8,$A$2:$A$8,0.95,1,1) -> 0.71459755

Sheet Profit Data
A1: Profitin_2012 | B1: Profitin_2011 | C1: Profitin_2010 | D1: Profitin_2009 | E1: Profitin_2008 | F1: Profitin_2007 | G1: Profitin_2006 | H1: Product Family
A2: -938 | B2: -5593 | C2: 0 | D2: 0 | E2: 0 | F2: 0 | G2: 0 | H2: Planterware
A3: -660 | B3: -2860 | C3: -11 | D3: 0 | E3: 0 | F3: 0 | G3: 0 | H3: Planterware
A4: 0 | B4: 16020 | C4: 0 | D4: 0 | E4: 0 | F4: 0 | G4: 0 | H4: Self-Watering
A5: 0 | B5: 3500 | C5: 0 | D5: 0 | E5: 0 | F5: 0 | G5: 0 | H5: Self-Watering
A6: 0 | B6: 1500 | C6: 0 | D6: 0 | E6: 0 | F6: 0 | G6: 0 | H6: Self-Watering
A7: 0 | B7: 1500 | C7: 0 | D7: 0 | E7: 0 | F7: 0 | G7: 0 | H7: Self-Watering
A8: 0 | B8: 1250 | C8: 0 | D8: 0 | E8: 0 | F8: 0 | G8: 0 | H8: Self-Watering
A9: 0 | B9: 1250 | C9: 0 | D9: 0 | E9: 0 | F9: 0 | G9: 0 | H9: Self-Watering
A10: 0 | B10: 500 | C10: 0 | D10: 0 | E10: 0 | F10: 0 | G10: 0 | H10: Self-Watering
A11: 0 | B11: 455 | C11: 0 | D11: 0 | E11: 0 | F11: 0 | G11: 0 | H11: Self-Watering
A12: 0 | B12: 400 | C12: 0 | D12: 0 | E12: 0 | F12: 0 | G12: 0 | H12: Self-Watering
A13: 0 | B13: 370 | C13: 0 | D13: 0 | E13: 0 | F13: 0 | G13: 0 | H13: Self-Watering
... A203: 164606 | B203: 147956 | C203: 322452 | D203: 8450 | E203: 0 | F203: 0 | G203: 0 | H203: Bins
D208: Years | E208: Bins | F208: Planterware | G208: Self Watering | H208: Total Profit | K208: Years | L208: Bins Profit % | M208: Planterware Profit % | N208: Self Watering Profit %
D209: 2006 | E209: =SUM(G2:G20) -> 0 | F209: =SUM(G22:G58) -> 0 | G209: =SUM(G59:G203) -> 943793.2 | H209: 943793 | K209: 2006 | L209: =E209/H209 -> 0 | M209: =F209/H209 -> 0 | N209: =G209/H209 -> 1.0000002
D210: 2007 | E210: =SUM(F2:F21) -> 0 | F210: =SUM(F22:F58) -> 1468.8 | G210: =SUM(F59:F203) -> 1026848 | H210: 1028317 | K210: 2007 | L210: =E210/H210 -> 0 | M210: =F210/H210 -> 0.0014283533 | N210: =G210/H210 -> 0.99857145
D211: 2008 | E211: =SUM(E2:E21) -> 4104 | F211: =SUM(E22:E58) -> 6487.2 | G211: =SUM(E59:E203) -> 971913.4 | H211: 982505 | K211: 2008 | L211: =E211/H211 -> 0.004177078 | M211: =F211/H211 -> 0.0066027145 | N211: =G211/H211 -> 0.9892198
D212: 2009 | E212: =SUM(D2:D21) -> 108 | F212: =SUM(D22:D58) -> 1849.8 | G212: =SUM(D59:D203) -> 834856.2 | H212: 836814 | K212: 2009 | L212: =E212/H212 -> 0.00012906094 | M212: =F212/H212 -> 0.0022105271 | N212: =G212/H212 -> 0.99766041
D213: 2010 | E213: =SUM(C2:C21) -> -11 | F213: =SUM(C22:C58) -> 9228.8 | G213: =SUM(C59:C203) -> 1236995.1 | H213: 1246213 | K213: 2010 | L213: =E213/H213 -> -8.8267415e-06 | M213: =F213/H213 -> 0.0074054756 | N213: =G213/H213 -> 0.99260327
D214: 2011 | E214: =SUM(B2:B21) -> 20129 | F214: =SUM(B22:B58) -> 8157.3 | G214: =SUM(B59:B203) -> 1039797 | H214: 1068083 | K214: 2011 | L214: =E214/H214 -> 0.018845914 | M214: =F214/H214 -> 0.0076373278 | N214: =G214/H214 -> 0.97351704
D215: 2012 | E215: =SUM(A2:A21) -> -1598 | F215: =SUM(B22:B58) -> 8157.3 | G215: =SUM(A59:A203) -> 1470701 | H215: 1475767 | K215: 2012 | L215: =E215/H215 -> -0.0010828268 | M215: =F215/H215 -> 0.0055274986 | N215: =G215/H215 -> 0.99656721
I220: Year | J220: Total Profit | K220: Total Sales
I221: 2006 | J221: 943793 | K221: 24122
I222: 2007 | J222: 1028317 | K222: 25891
I223: 2008 | J223: 982505 | K223: 24809
I224: 2009 | J224: 836814 | K224: 23226
I225: 2010 | J225: 1246213 | K225: 22470
I226: 2011 | J226: 1068083 | K226: 24843
I227: 2012 | J227: 1475767 | K227: 29941
H255: Sales_in2012 | I255: Profit_in2012 | J255: Sales_in2011 | K255: Profit_in2011 | L255: Sales_in2010 | M255: Profit_in2010 | N255: Sales_in2009 | O255: Profit_in2009 | P255: Sales_in2008 | Q255: Profit_in2008 | R255: Sales_in2007 | S255: Profit_in2007 | T255: Sales_in_2006 | U255: Profit_in2006 | V255: Total_of_Sales | W255: Product Family | X255: Due Date Performance
H256: 0 | I256: 0 | J256: 1 | K256: 220 | L256: 0 | M256: 0 | N256: 1 | O256: 108 | P256: 38 | Q256: 4104 | R256: 0 | S256: 0 | T256: 0 | U256: 0 | V256: 40 | W256: Self-Watering | X256: 98
H257: 0 | I257: 0 | J257: 0 | K257: 0 | L257: 0 | M257: 0 | N257: 0 | O257: 0 | P257: 12 | Q257: 4932 | R257: 0 | S257: 0 | T257: 0 | U257: 0 | V257: 12 | W257: Self-Watering | X257: 96
H258: 0 | I258: 0 | J258: 0 | K258: 0 | L258: 0 | M258: 0 | N258: 1 | O258: 183.4 | P258: 0 | Q258: 0 | R258: 0 | S258: 0 | T258: 0 | U258: 0 | V258: 1 | W258: Self-Watering | X258: 93
H259: 0 | I259: 0 | J259: 0 | K259: 0 | L259: 0 | M259: 0 | N259: 0 | O259: 0 | P259: 0 | Q259: 0 | R259: 0 | S259: 0 | T259: 0 | U259: 0 | V259: 0 | W259: Planterware | X259: 93
H260: 0 | I260: 0 | J260: 0 | K260: 0 | L260: 0 | M260: 0 | N260: 0 | O260: 0 | P260: 0 | Q260: 0 | R260: 0 | S260: 0 | T260: 0 | U260: 0 | V260: 0 | W260: Planterware | X260: 99
H261: 2 | I261: 416.8 | J261: 34 | K261: 11296.8 | L261: 36 | M261: 7502.4 | N261: 2 | O261: 416.8 | P261: 0 | Q261: 0 | R261: 0 | S261: 0 | T261: 0 | U261: 0 | V261: 74 | W261: Self-Watering | X261: 92
H262: 5 | I262: 690 | J262: 0 | K262: -560 | L262: 0 | M262: 0 | N262: 2 | O262: 276 | P262: 52 | Q262: 7176 | R262: 0 | S262: 0 | T262: 0 | U262: 0 | V262: 59 | W262: Self-Watering | X262: 95
H263: 5 | I263: 430 | J263: 7 | K263: 630 | L263: 3 | M263: 258 | N263: 8 | O263: 688 | P263: 0 | Q263: 0 | R263: 0 | S263: 0 | T263: 0 | U263: 0 | V263: 23 | W263: Bins | X263: 91
H264: 7 | I264: 2072 | J264: 2 | K264: -178 | L264: 3 | M264: 888 | N264: 1 | O264: 296 | P264: 8 | Q264: 2368 | R264: 0 | S264: 0 | T264: 0 | U264: 0 | V264: 21 | W264: Self-Watering | X264: 95
...

Sheet DraftDataset (2)
A1: Product | B1: Description | C1: Colour | D1: Powder_weight_kg | E1: Powder_Cost | F1: Selling_Price_Pound | G1: Profit | H1: Sales_in2012 | I1: Profit_in2012 | J1: Sales_in2011 | K1: Profit_in2011 | L1: Sales_in2010 | M1: Profit_in2010 | N1: Sales_in2009 | O1: Profit_in2009 | P1: Sales_in2008 | Q1: Profit_in2008 | R1: Sales_in2007 | S1: Profit_in2007 | T1: Sales_in_2006 | U1: Profit_in2006 | V1: Total_of_Sales | W1: Product Family | X1: Due Date Performance
A2: MSP 1P | B2: Meter sq planter (1) | C2: Black | D2: 40 | E2: 112 | F2: 220 | G2: 108 | H2: 0 | I2: 0 | J2: 1 | K2: 220 | L2: 0 | M2: 0 | N2: 1 | O2: 108 | P2: 38 | Q2: 4104 | R2: 0 | S2: 0 | T2: 0 | U2: 0 | V2: 40 | W2: Self-Watering | X2: 98
A3: MSP 4P | B3: Meter sq planter (4) | C3: Black | D3: 60 | E3: 168 | F3: 579 | G3: 411 | H3: 0 | I3: 0 | J3: 0 | K3: 0 | L3: 0 | M3: 0 | N3: 0 | O3: 0 | P3: 12 | Q3: 4932 | R3: 0 | S3: 0 | T3: 0 | U3: 0 | V3: 12 | W3: Self-Watering | X3: 96
A4: OCT 2P | B4: Octagonal fountain (2) | C4: Black | D4: 47 | E4: 131.6 | F4: 315 | G4: 183.4 | H4: 0 | I4: 0 | J4: 0 | K4: 0 | L4: 0 | M4: 0 | N4: 1 | O4: 183.4 | P4: 0 | Q4: 0 | R4: 0 | S4: 0 | T4: 0 | U4: 0 | V4: 1 | W4: Self-Watering | X4: 93
A5: J-C41 | B5: Cylinder | C5: Black | D5: 14 | E5: 39.2 | F5: 30 | G5: -9.2 | H5: 0 | I5: 0 | J5: 0 | K5: 0 | L5: 0 | M5: 0 | N5: 0 | O5: 0 | P5: 0 | Q5: 0 | R5: 0 | S5: 0 | T5: 0 | U5: 0 | V5: 0 | W5: Planterware | X5: 93
A6: J-C45-T3 | B6: Cylinder | C6: Black | D6: 17 | E6: 47.6 | F6: 38 | G6: -9.6 | H6: 0 | I6: 0 | J6: 0 | K6: 0 | L6: 0 | M6: 0 | N6: 0 | O6: 0 | P6: 0 | Q6: 0 | R6: 0 | S6: 0 | T6: 0 | U6: 0 | V6: 0 | W6: Planterware | X6: 99
A7: MSP 2P | B7: Meter sq planter (2) | C7: Black | D7: 47 | E7: 131.6 | F7: 340 | G7: 208.4 | H7: 2 | I7: 416.8 | J7: 34 | K7: 11296.8 | L7: 36 | M7: 7502.4 | N7: 2 | O7: 416.8 | P7: 0 | Q7: 0 | R7: 0 | S7: 0 | T7: 0 | U7: 0 | V7: 74 | W7: Self-Watering | X7: 92
A8: OCT 1P | B8: Octagonal fountain (1) | C8: Black | D8: 40 | E8: 112 | F8: 250 | G8: 138 | H8: 5 | I8: 690 | J8: 0 | K8: -560 | L8: 0 | M8: 0 | N8: 2 | O8: 276 | P8: 52 | Q8: 7176 | R8: 0 | S8: 0 | T8: 0 | U8: 0 | V8: 59 | W8: Self-Watering | X8: 95
A9: SCW 0P | B9: Screwball post bin | C9: Black | D9: 5 | E9: 14 | F9: 100 | G9: 86 | H9: 5 | I9: 430 | J9: 7 | K9: 630 | L9: 3 | M9: 258 | N9: 8 | O9: 688 | P9: 0 | Q9: 0 | R9: 0 | S9: 0 | T9: 0 | U9: 0 | V9: 23 | W9: Bins | X9: 91
A10: OCT 3P | B10: Octagonal fountain (3) | C10: Black | D10: 55 | E10: 154 | F10: 450 | G10: 296 | H10: 7 | I10: 2072 | J10: 2 | K10: -178 | L10: 3 | M10: 888 | N10: 1 | O10: 296 | P10: 8 | Q10: 2368 | R10: 0 | S10: 0 | T10: 0 | U10: 0 | V10: 21 | W10: Self-Watering | X10: 95
A11: WBX 0P | B11: Wall and window box | C11: Black | D11: 6 | E11: 16.8 | F11: 60 | G11: 43.2 | H11: 10 | I11: 432 | J11: 10 | K11: 432 | L11: 12 | M11: 518.4 | N11: 13 | O11: 561.6 | P11: 36 | Q11: 1555.2 | R11: 34 | S11: 1468.8 | T11: 0 | U11: 0 | V11: 115 | W11: Self-Watering | X11: 98
A12: POOP 0P | B12: Poo bin | C12: Black | D12: 7 | E12: 19.6 | F12: 120 | G12: 100.4 | H12: 10 | I12: 1004 | J12: 0 | K12: -196 | L12: 0 | M12: 0 | N12: 0 | O12: 0 | P12: 0 | Q12: 0 | R12: 0 | S12: 0 | T12: 0 | U12: 0 | V12: 10 | W12: Bins | X12: 98
A13: PAR 1P | B13: Parot bin | C13: Black | D13: 30 | E13: 84 | F13: 280 | G13: 196 | H13: 12 | I13: 2352 | J13: 12 | K13: 2352 | L13: 9 | M13: 1764 | N13: 10 | O13: 1960 | P13: 13 | Q13: 2548 | R13: 13 | S13: 2548 | T13: 15 | U13: 2940 | V13: 69 | W13: Bins | X13: 93
... A97: CNS 1P | B97: Cup and Saucer on pole | C97: Standard Green | D97: 7 | E97: 21 | F97: 55 | G97: 34 | H97: 1578 | I97: 53652 | J97: 1450 | K97: 46612 | L97: 1135 | M97: 38590 | N97: 957 | O97: 32538 | P97: 2300 | Q97: 78200 | R97: 2780 | S97: 94520 | T97: 2800 | U97: 95200 | V97: 10200 | W97: Self-Watering | X97: 95

Sheet CleanedDataset
A1: Product | B1: Description | C1: Colour | D1: Powder_weight_kg | E1: Powder_Cost | F1: Selling_Price_Pound | G1: Profit | H1: Profit_Margin | I1: Salesin_2012 | J1: Profitin_2012 | K1: Salesin_2011 | L1: Profitin_2011 | M1: Salesin_2010 | N1: Profitin_2010 | O1: Salesin_2009 | P1: Profitin_2009 | Q1: Salesin_2008 | R1: Profitin_2008 | S1: Salesin_2007 | T1: Profitin_2007 | U1: Salesin_2006 | V1: Profitin_2006 | W1: Total Nr of Sales | X1: Product__Family | Y1: Due Date Performance/% | Z1: Total_Powder_Weight_kg
A2: ACT 1P | B2: Enviro can recycle - post | C2: Black | D2: 8 | E2: =D2*2.8 -> 22.4 | F2: 125 | G2: =F2-E2 -> 102.6 | H2: =(CleanedDataset!$F31-CleanedDataset!$E31)/CleanedDataset!$F31 -> 0.66666667 | I2: 45 | J2: =I2*F2-I2*E2 -> 4617 | K2: 50 | L2: =K2*F2-I2*E2 -> 5242 | M2: 80 | N2: =M2*F2-M2*E2 -> 8208 | O2: 50 | P2: =O2*F2-O2*E2 -> 5130 | Q2: 120 | R2: =Q2*F2-Q2*E2 -> 12312 | S2: 103 | T2: =S2*F2-S2*E2 -> 10567.8 | U2: 69 | V2: =U2*F2-U2*E2 -> 7079.4 | W2: =SUM(S2,Q2,O2,M2,K2,I2) -> 448 | X2: Bins | Y2: 100 | Z2: =D2*I2 -> 360
A3: AMB 1P | B3: Bear bin | C3: Black | D3: 45 | E3: =D3*2.8 -> 126 | F3: 300 | G3: =F3-E3 -> 174 | H3: =(CleanedDataset!$F20-CleanedDataset!$E20)/CleanedDataset!$F20 -> 0.7 | I3: 23 | J3: =I3*F3-I3*E3 -> 4002 | K3: 20 | L3: =K3*F3-I3*E3 -> 3102 | M3: 15 | N3: =M3*F3-M3*E3 -> 2610 | O3: 10 | P3: =O3*F3-O3*E3 -> 1740 | Q3: 13 | R3: =Q3*F3-Q3*E3 -> 2262 | S3: 20 | T3: =S3*F3-S3*E3 -> 3480 | U3: 15 | V3: =U3*F3-U3*E3 -> 2610 | W3: =SUM(S3,Q3,O3,M3,K3,I3) -> 101 | X3: Bins | Y3: 98 | Z3: =D3*I3 -> 1035
A4: AMP 1P | B4: Ample bin | C4: Black | D4: 20 | E4: =D4*2.8 -> 56 | F4: 150 | G4: =F4-E4 -> 94 | H4: =(CleanedDataset!$F47-CleanedDataset!$E47)/CleanedDataset!$F47 -> 0.64102564 | I4: 230 | J4: =I4*F4-I4*E4 -> 21620 | K4: 215 | L4: =K4*F4-I4*E4 -> 19370 | M4: 150 | N4: =M4*F4-M4*E4 -> 14100 | O4: 20 | P4: =O4*F4-O4*E4 -> 1880 | Q4: 80 | R4: =Q4*F4-Q4*E4 -> 7520 | S4: 40 | T4: =S4*F4-S4*E4 -> 3760 | U4: 50 | V4: =U4*F4-U4*E4 -> 4700 | W4: =SUM(S4,Q4,O4,M4,K4,I4) -> 735 | X4: Bins | Y4: 97 | Z4: =D4*I4 -> 4600
A5: BBU 0P | B5: Full barrier basket | C5: Cherry | D5: 7.5 | E5: =D5*3 -> 22.5 | F5: 70 | G5: =F5-E5 -> 47.5 | H5: =(CleanedDataset!$F73-CleanedDataset!$E73)/CleanedDataset!$F73 -> 0.82222222 | I5: 5 | J5: =I5*F5-I5*E5 -> 237.5 | K5: 0 | L5: =K5*F5-I5*E5 -> -112.5 | M5: 0 | N5: =M5*F5-M5*E5 -> 0 | O5: 0 | P5: =O5*F5-O5*E5 -> 0 | Q5: 0 | R5: =Q5*F5-Q5*E5 -> 0 | S5: 0 | T5: =S5*F5-S5*E5 -> 0 | U5: 0 | V5: =U5*F5-U5*E5 -> 0 | W5: =SUM(S5,Q5,O5,M5,K5,I5) -> 5 | X5: Self-Watering | Y5: 96 | Z5: =D5*I5 -> 37.5
A6: BBU 0P | B6: Full barrier basket | C6: Standard Green | D6: 7.5 | E6: =D6*3 -> 22.5 | F6: 70 | G6: =F6-E6 -> 47.5 | H6: =(CleanedDataset!$F159-CleanedDataset!$E159)/CleanedDataset!$F159 -> 0.25 | I6: 360 | J6: =I6*F6-I6*E6 -> 17100 | K6: 245 | L6: =K6*F6-I6*E6 -> 9050 | M6: 133 | N6: =M6*F6-M6*E6 -> 6317.5 | O6: 88 | P6: =O6*F6-O6*E6 -> 4180 | Q6: 10 | R6: =Q6*F6-Q6*E6 -> 475 | S6: 0 | T6: =S6*F6-S6*E6 -> 0 | U6: 0 | V6: =U6*F6-U6*E6 -> 0 | W6: =SUM(S6,Q6,O6,M6,K6,I6) -> 836 | X6: Self-Watering | Y6: 99 | Z6: =D6*I6 -> 2700
A7: BBU 0P | B7: Full barrier basket | C7: Black | D7: 7.5 | E7: =D7*2.8 -> 21 | F7: 58 | G7: =F7-E7 -> 37 | H7: =(CleanedDataset!$F41-CleanedDataset!$E41)/CleanedDataset!$F41 -> 0.56444444 | I7: 94 | J7: =I7*F7-I7*E7 -> 3478 | K7: 138 | L7: =K7*F7-I7*E7 -> 6030 | M7: 124 | N7: =M7*F7-M7*E7 -> 4588 | O7: 72 | P7: =O7*F7-O7*E7 -> 2664 | Q7: 10 | R7: =Q7*F7-Q7*E7 -> 370 | S7: 0 | T7: =S7*F7-S7*E7 -> 0 | U7: 0 | V7: =U7*F7-U7*E7 -> 0 | W7: =SUM(S7,Q7,O7,M7,K7,I7) -> 438 | X7: Self-Watering | Y7: 99 | Z7: =D7*I7 -> 705
A8: BBU 1P | B8: Barrier Basket | C8: Pink Granite | D8: 6 | E8: =D8*3.2 -> 19.2 | F8: 55 | G8: =F8-E8 -> 35.8 | H8: =(CleanedDataset!$F126-CleanedDataset!$E126)/CleanedDataset!$F126 -> 0.61891892 | I8: 530 | J8: =I8*F8-I8*E8 -> 18974 | K8: 135 | L8: =K8*F8-I8*E8 -> -2751 | M8: 0 | N8: =M8*F8-M8*E8 -> 0 | O8: 0 | P8: =O8*F8-O8*E8 -> 0 | Q8: 0 | R8: =Q8*F8-Q8*E8 -> 0 | S8: 0 | T8: =S8*F8-S8*E8 -> 0 | U8: 0 | V8: =U8*F8-U8*E8 -> 0 | W8: =SUM(S8,Q8,O8,M8,K8,I8) -> 665 | X8: Self-Watering | Y8: 90 | Z8: =D8*I8 -> 3180
A9: BBU 1P | B9: Barrier Basket | C9: Standard Green | D9: 6 | E9: =D9*3 -> 18 | F9: 50 | G9: =F9-E9 -> 32 | H9: =(CleanedDataset!$F162-CleanedDataset!$E162)/CleanedDataset!$F162 -> 0.83666667 | I9: 450 | J9: =I9*F9-I9*E9 -> 14400 | K9: 300 | L9: =K9*F9-I9*E9 -> 6900 | M9: 230 | N9: =M9*F9-M9*E9 -> 7360 | O9: 200 | P9: =O9*F9-O9*E9 -> 6400 | Q9: 225 | R9: =Q9*F9-Q9*E9 -> 7200 | S9: 705 | T9: =S9*F9-S9*E9 -> 22560 | U9: 680 | V9: =U9*F9-U9*E9 -> 21760 | W9: =SUM(S9,Q9,O9,M9,K9,I9) -> 2110 | X9: Self-Watering | Y9: 92 | Z9: =D9*I9 -> 2700
A10: BBU 1P | B10: Barrier Basket | C10: Black | D10: 6 | E10: =D10*2.8 -> 16.8 | F10: 40 | G10: =F10-E10 -> 23.2 | H10: =(CleanedDataset!$F53-CleanedDataset!$E53)/CleanedDataset!$F53 -> 0.7 | I10: 405 | J10: =I10*F10-I10*E10 -> 9396 | K10: 534 | L10: =K10*F10-I10*E10 -> 14556 | M10: 987 | N10: =M10*F10-M10*E10 -> 22898.4 | O10: 1917 | P10: =O10*F10-O10*E10 -> 44474.4 | Q10: 1047 | R10: =Q10*F10-Q10*E10 -> 24290.4 | S10: 326 | T10: =S10*F10-S10*E10 -> 7563.2 | U10: 857 | V10: =U10*F10-U10*E10 -> 19882.4 | W10: =SUM(S10,Q10,O10,M10,K10,I10) -> 5216 | X10: Self-Watering | Y10: 92 | Z10: =D10*I10 -> 2430
A11: BBU 1PL | B11: Barrier Basket Liner | C11: Standard Green | D11: 3.5 | E11: =D11*3 -> 10.5 | F11: 35 | G11: =F11-E11 -> 24.5 | H11: =(CleanedDataset!$F167-CleanedDataset!$E167)/CleanedDataset!$F167 -> 0.29292929 | I11: 1350 | J11: =I11*F11-I11*E11 -> 33075 | K11: 1200 | L11: =K11*F11-I11*E11 -> 27825 | M11: 567 | N11: =M11*F11-M11*E11 -> 13891.5 | O11: 200 | P11: =O11*F11-O11*E11 -> 4900 | Q11: 540 | R11: =Q11*F11-Q11*E11 -> 13230 | S11: 1250 | T11: =S11*F11-S11*E11 -> 30625 | U11: 890 | V11: =U11*F11-U11*E11 -> 21805 | W11: =SUM(S11,Q11,O11,M11,K11,I11) -> 5107 | X11: Self-Watering | Y11: 91 | Z11: =D11*I11 -> 4725
A12: BBU 1PL | B12: Barrier Basket Liner | C12: Black | D12: 3.5 | E12: =D12*2.8 -> 9.8 | F12: 25 | G12: =F12-E12 -> 15.2 | H12: =(CleanedDataset!$F56-CleanedDataset!$E56)/CleanedDataset!$F56 -> 0.68802228 | I12: 604 | J12: =I12*F12-I12*E12 -> 9180.8 | K12: 339 | L12: =K12*F12-I12*E12 -> 2555.8 | M12: 853 | N12: =M12*F12-M12*E12 -> 12965.6 | O12: 2331 | P12: =O12*F12-O12*E12 -> 35431.2 | Q12: 1049 | R12: =Q12*F12-Q12*E12 -> 15944.8 | S12: 326 | T12: =S12*F12-S12*E12 -> 4955.2 | U12: 708 | V12: =U12*F12-U12*E12 -> 10761.6 | W12: =SUM(S12,Q12,O12,M12,K12,I12) -> 5502 | X12: Self-Watering | Y12: 99 | Z12: =D12*I12 -> 2114
A13: BHV 5P | B13: Bee hive fountain (5) | C13: Guerney Granite | D13: 55 | E13: =D13*3.2 -> 176 | F13: 615 | G13: =F13-E13 -> 439 | H13: =(CleanedDataset!$F82-CleanedDataset!$E82)/CleanedDataset!$F82 -> 0.58588235 | I13: 57 | J13: =I13*F13-I13*E13 -> 25023 | K13: 35 | L13: =K13*F13-I13*E13 -> 11493 | M13: 0 | N13: =M13*F13-M13*E13 -> 0 | O13: 0 | P13: =O13*F13-O13*E13 -> 0 | Q13: 0 | R13: =Q13*F13-Q13*E13 -> 0 | S13: 0 | T13: =S13*F13-S13*E13 -> 0 | U13: 0 | V13: =U13*F13-U13*E13 -> 0 | W13: =SUM(S13,Q13,O13,M13,K13,I13) -> 92 | X13: Self-Watering | Y13: 93 | Z13: =D13*I13 -> 3135
A14: BHV 5P | B14: Bee hive fountain (5) | C14: Pink Granite | D14: 55 | E14: =D14*3.2 -> 176 | F14: 600 | G14: =F14-E14 -> 424 | H14: =(CleanedDataset!$F117-CleanedDataset!$E117)/CleanedDataset!$F117 -> 0.57333333 | I14: 35 | J14: =I14*F14-I14*E14 -> 14840 | K14: 14 | L14: =K14*F14-I14*E14 -> 2240 | M14: 0 | N14: =M14*F14-M14*E14 -> 0 | O14: 0 | P14: =O14*F14-O14*E14 -> 0 | Q14: 0 | R14: =Q14*F14-Q14*E14 -> 0 | S14: 0 | T14: =S14*F14-S14*E14 -> 0 | U14: 0 | V14: =U14*F14-U14*E14 -> 0 | W14: =SUM(S14,Q14,O14,M14,K14,I14) -> 49 | X14: Self-Watering | Y14: 90 | Z14: =D14*I14 -> 1925
A15: BHV 5P | B15: Bee hive fountain (5) | C15: Standard Green | D15: 55 | E15: =D15*3 -> 165 | F15: 600 | G15: =F15-E15 -> 435 | H15: =(CleanedDataset!$F148-CleanedDataset!$E148)/CleanedDataset!$F148 -> 0.59351351 | I15: 66 | J15: =I15*F15-I15*E15 -> 28710 | K15: 35 | L15: =K15*F15-I15*E15 -> 10110 | M15: 12 | N15: =M15*F15-M15*E15 -> 5220 | O15: 15 | P15: =O15*F15-O15*E15 -> 6525 | Q15: 33 | R15: =Q15*F15-Q15*E15 -> 14355 | S15: 50 | T15: =S15*F15-S15*E15 -> 21750 | U15: 45 | V15: =U15*F15-U15*E15 -> 19575 | W15: =SUM(S15,Q15,O15,M15,K15,I15) -> 211 | X15: Self-Watering | Y15: 94 | Z15: =D15*I15 -> 3630
A16: BHV 5P | B16: Bee hive fountain (5) | C16: Black | D16: 55 | E16: =D16*2.8 -> 154 | F16: 530 | G16: =F16-E16 -> 376 | H16: =(CleanedDataset!$F33-CleanedDataset!$E33)/CleanedDataset!$F33 -> 0.6 | I16: 58 | J16: =I16*F16-I16*E16 -> 21808 | K16: 75 | L16: =K16*F16-I16*E16 -> 30818 | M16: 39 | N16: =M16*F16-M16*E16 -> 14664 | O16: 16 | P16: =O16*F16-O16*E16 -> 6016 | Q16: 21 | R16: =Q16*F16-Q16*E16 -> 7896 | S16: 60 | T16: =S16*F16-S16*E16 -> 22560 | U16: 64 | V16: =U16*F16-U16*E16 -> 24064 | W16: =SUM(S16,Q16,O16,M16,K16,I16) -> 269 | X16: Self-Watering | Y16: 100 | Z16: =D16*I16 -> 3190
A17: BHV 6P | B17: Bee hive fountain (6) | C17: Guerney Granite | D17: 65 | E17: =D17*3.2 -> 208 | F17: 700 | G17: =F17-E17 -> 492 | H17: =(CleanedDataset!$F78-CleanedDataset!$E78)/CleanedDataset!$F78 -> -0.275 | I17: 5 | J17: =I17*F17-I17*E17 -> 2460 | K17: 0 | L17: =K17*F17-I17*E17 -> -1040 | M17: 0 | N17: =M17*F17-M17*E17 -> 0 | O17: 0 | P17: =O17*F17-O17*E17 -> 0 | Q17: 0 | R17: =Q17*F17-Q17*E17 -> 0 | S17: 0 | T17: =S17*F17-S17*E17 -> 0 | U17: 0 | V17: =U17*F17-U17*E17 -> 0 | W17: =SUM(S17,Q17,O17,M17,K17,I17) -> 5 | X17: Self-Watering | Y17: 99 | Z17: =D17*I17 -> 325
A18: BHV 6P | B18: Bee hive fountain (6) | C18: Moss Stone | D18: 65 | E18: =D18*3.2 -> 208 | F18: 700 | G18: =F18-E18 -> 492 | H18: =(CleanedDataset!$F99-CleanedDataset!$E99)/CleanedDataset!$F99 -> 0.0625 | I18: 0 | J18: =I18*F18-I18*E18 -> 0 | K18: 5 | L18: =K18*F18-I18*E18 -> 3500 | M18: 0 | N18: =M18*F18-M18*E18 -> 0 | O18: 0 | P18: =O18*F18-O18*E18 -> 0 | Q18: 0 | R18: =Q18*F18-Q18*E18 -> 0 | S18: 0 | T18: =S18*F18-S18*E18 -> 0 | U18: 0 | V18: =U18*F18-U18*E18 -> 0 | W18: =SUM(S18,Q18,O18,M18,K18,I18) -> 5 | X18: Self-Watering | Y18: 98 | Z18: =D18*I18 -> 0
A19: BHV 6P | B19: Bee hive fountain (6) | C19: Pink Granite | D19: 65 | E19: =D19*3.2 -> 208 | F19: 700 | G19: =F19-E19 -> 492 | H19: =(CleanedDataset!$F122-CleanedDataset!$E122)/CleanedDataset!$F122 -> 0.49090909 | I19: 53 | J19: =I19*F19-I19*E19 -> 26076 | K19: 28 | L19: =K19*F19-I19*E19 -> 8576 | M19: 0 | N19: =M19*F19-M19*E19 -> 0 | O19: 0 | P19: =O19*F19-O19*E19 -> 0 | Q19: 0 | R19: =Q19*F19-Q19*E19 -> 0 | S19: 0 | T19: =S19*F19-S19*E19 -> 0 | U19: 0 | V19: =U19*F19-U19*E19 -> 0 | W19: =SUM(S19,Q19,O19,M19,K19,I19) -> 81 | X19: Self-Watering | Y19: 93 | Z19: =D19*I19 -> 3445
A20: BHV 6P | B20: Bee hive fountain (6) | C20: Light Green | D20: 65 | E20: =D20*3 -> 195 | F20: 650 | G20: =F20-E20 -> 455 | H20: =(CleanedDataset!$F84-CleanedDataset!$E84)/CleanedDataset!$F84 -> 0.25 | I20: 3 | J20: =I20*F20-I20*E20 -> 1365 | K20: 0 | L20: =K20*F20-I20*E20 -> -585 | M20: 0 | N20: =M20*F20-M20*E20 -> 0 | O20: 0 | P20: =O20*F20-O20*E20 -> 0 | Q20: 0 | R20: =Q20*F20-Q20*E20 -> 0 | S20: 0 | T20: =S20*F20-S20*E20 -> 0 | U20: 0 | V20: =U20*F20-U20*E20 -> 0 | W20: =SUM(S20,Q20,O20,M20,K20,I20) -> 3 | X20: Self-Watering | Y20: 98 | Z20: =D20*I20 -> 195
A21: BHV 6P | B21: Bee hive fountain (6) | C21: Standard Green | D21: 65 | E21: =D21*3 -> 195 | F21: 650 | G21: =F21-E21 -> 455 | H21: =(CleanedDataset!$F152-CleanedDataset!$E152)/CleanedDataset!$F152 -> 0.648 | I21: 158 | J21: =I21*F21-I21*E21 -> 71890 | K21: 113 | L21: =K21*F21-I21*E21 -> 42640 | M21: 250 | N21: =M21*F21-M21*E21 -> 113750 | O21: 0 | P21: =O21*F21-O21*E21 -> 0 | Q21: 0 | R21: =Q21*F21-Q21*E21 -> 0 | S21: 0 | T21: =S21*F21-S21*E21 -> 0 | U21: 0 | V21: =U21*F21-U21*E21 -> 0 | W21: =SUM(S21,Q21,O21,M21,K21,I21) -> 521 | X21: Self-Watering | Y21: 97 | Z21: =D21*I21 -> 10270
A22: BHV 6P | B22: Bee hive fountain (6) | C22: Black | D22: 65 | E22: =D22*2.8 -> 182 | F22: 584 | G22: =F22-E22 -> 402 | H22: =(CleanedDataset!$F32-CleanedDataset!$E32)/CleanedDataset!$F32 -> 0.66666667 | I22: 51 | J22: =I22*F22-I22*E22 -> 20502 | K22: 78 | L22: =K22*F22-I22*E22 -> 36270 | M22: 193 | N22: =M22*F22-M22*E22 -> 77586 | O22: 0 | P22: =O22*F22-O22*E22 -> 0 | Q22: 0 | R22: =Q22*F22-Q22*E22 -> 0 | S22: 0 | T22: =S22*F22-S22*E22 -> 0 | U22: 0 | V22: =U22*F22-U22*E22 -> 0 | W22: =SUM(S22,Q22,O22,M22,K22,I22) -> 322 | X22: Self-Watering | Y22: 94 | Z22: =D22*I22 -> 3315
A23: BRL 0P | B23: Barrel | C23: Brown | D23: 15 | E23: =D23*3 -> 45 | F23: 75 | G23: =F23-E23 -> 30 | H23: =(CleanedDataset!$F62-CleanedDataset!$E62)/CleanedDataset!$F62 -> 0.72 | I23: 496 | J23: =I23*F23-I23*E23 -> 14880 | K23: 557 | L23: =K23*F23-I23*E23 -> 19455 | M23: 0 | N23: =M23*F23-M23*E23 -> 0 | O23: 0 | P23: =O23*F23-O23*E23 -> 0 | Q23: 0 | R23: =Q23*F23-Q23*E23 -> 0 | S23: 0 | T23: =S23*F23-S23*E23 -> 0 | U23: 0 | V23: =U23*F23-U23*E23 -> 0 | W23: =SUM(S23,Q23,O23,M23,K23,I23) -> 1053 | X23: Self-Watering | Y23: 91 | Z23: =D23*I23 -> 7440
A24: CAS 0P | B24: Cup and Saucer | C24: Orange | D24: 7 | E24: =D24*3 -> 21 | F24: 40 | G24: =F24-E24 -> 19 | H24: =(CleanedDataset!$F102-CleanedDataset!$E102)/CleanedDataset!$F102 -> 0.5890411 | I24: 6 | J24: =I24*F24-I24*E24 -> 114 | K24: 15 | L24: =K24*F24-I24*E24 -> 474 | M24: 0 | N24: =M24*F24-M24*E24 -> 0 | O24: 0 | P24: =O24*F24-O24*E24 -> 0 | Q24: 0 | R24: =Q24*F24-Q24*E24 -> 0 | S24: 0 | T24: =S24*F24-S24*E24 -> 0 | U24: 0 | V24: =U24*F24-U24*E24 -> 0 | W24: =SUM(S24,Q24,O24,M24,K24,I24) -> 21 | X24: Self-Watering | Y24: 94 | Z24: =D24*I24 -> 42
A25: CAS 0P | B25: Cup and Saucer | C25: Sky Blue | D25: 7 | E25: =D25*3 -> 21 | F25: 40 | G25: =F25-E25 -> 19 | H25: =(CleanedDataset!$F133-CleanedDataset!$E133)/CleanedDataset!$F133 -> 0.70461538 | I25: 135 | J25: =I25*F25-I25*E25 -> 2565 | K25: 46 | L25: =K25*F25-I25*E25 -> -995 | M25: 0 | N25: =M25*F25-M25*E25 -> 0 | O25: 0 | P25: =O25*F25-O25*E25 -> 0 | Q25: 0 | R25: =Q25*F25-Q25*E25 -> 0 | S25: 0 | T25: =S25*F25-S25*E25 -> 0 | U25: 0 | V25: =U25*F25-U25*E25 -> 0 | W25: =SUM(S25,Q25,O25,M25,K25,I25) -> 181 | X25: Self-Watering | Y25: 95 | Z25: =D25*I25 -> 945
A26: CAS 0P | B26: Cup and Saucer | C26: Standard Green | D26: 7 | E26: =D26*3 -> 21 | F26: 40 | G26: =F26-E26 -> 19 | H26: =(CleanedDataset!$F166-CleanedDataset!$E166)/CleanedDataset!$F166 -> 0.87076923 | I26: 1300 | J26: =I26*F26-I26*E26 -> 24700 | K26: 1250 | L26: =K26*F26-I26*E26 -> 22700 | M26: 800 | N26: =M26*F26-M26*E26 -> 15200 | O26: 750 | P26: =O26*F26-O26*E26 -> 14250 | Q26: 1200 | R26: =Q26*F26-Q26*E26 -> 22800 | S26: 2050 | T26: =S26*F26-S26*E26 -> 38950 | U26: 1980 | V26: =U26*F26-U26*E26 -> 37620 | W26: =SUM(S26,Q26,O26,M26,K26,I26) -> 7350 | X26: Self-Watering | Y26: 97 | Z26: =D26*I26 -> 9100
A27: CAS 0P | B27: Cup and Saucer | C27: Black | D27: 7 | E27: =D27*2.8 -> 19.6 | F27: 30 | G27: =F27-E27 -> 10.4 | H27: =(CleanedDataset!$F61-CleanedDataset!$E61)/CleanedDataset!$F61 -> 0.76666667 | I27: 2132 | J27: =I27*F27-I27*E27 -> 22172.8 | K27: 2648 | L27: =K27*F27-I27*E27 -> 37652.8 | M27: 2712 | N27: =M27*F27-M27*E27 -> 28204.8 | O27: 1775 | P27: =O27*F27-O27*E27 -> 18460 | Q27: 2302 | R27: =Q27*F27-Q27*E27 -> 23940.8 | S27: 2250 | T27: =S27*F27-S27*E27 -> 23400 | U27: 2532 | V27: =U27*F27-U27*E27 -> 26332.8 | W27: =SUM(S27,Q27,O27,M27,K27,I27) -> 13819 | X27: Self-Watering | Y27: 91 | Z27: =D27*I27 -> 14924
A28: CAS 1P | B28: Cup and Saucer (HB) | C28: Light Sandstone | D28: 5 | E28: =D28*3.2 -> 16 | F28: 60 | G28: =F28-E28 -> 44 | H28: =(CleanedDataset!$F97-CleanedDataset!$E97)/CleanedDataset!$F97 -> 0.45 | I28: 23 | J28: =I28*F28-I28*E28 -> 1012 | K28: 35 | L28: =K28*F28-I28*E28 -> 1732 | M28: 0 | N28: =M28*F28-M28*E28 -> 0 | O28: 0 | P28: =O28*F28-O28*E28 -> 0 | Q28: 0 | R28: =Q28*F28-Q28*E28 -> 0 | S28: 0 | T28: =S28*F28-S28*E28 -> 0 | U28: 0 | V28: =U28*F28-U28*E28 -> 0 | W28: =SUM(S28,Q28,O28,M28,K28,I28) -> 58 | X28: Self-Watering | Y28: 95 | Z28: =D28*I28 -> 115
A29: CAS 1P | B29: Cup and Saucer (HB) | C29: Standard Green | D29: 5 | E29: =D29*3 -> 15 | F29: 50 | G29: =F29-E29 -> 35 | H29: =(CleanedDataset!$F164-CleanedDataset!$E164)/CleanedDataset!$F164 -> 0.664 | I29: 860 | J29: =I29*F29-I29*E29 -> 30100 | K29: 744 | L29: =K29*F29-I29*E29 -> 24300 | M29: 343 | N29: =M29*F29-M29*E29 -> 12005 | O29: 320 | P29: =O29*F29-O29*E29 -> 11200 | Q29: 287 | R29: =Q29*F29-Q29*E29 -> 10045 | S29: 680 | T29: =S29*F29-S29*E29 -> 23800 | U29: 623 | V29: =U29*F29-U29*E29 -> 21805 | W29: =SUM(S29,Q29,O29,M29,K29,I29) -> 3234 | X29: Self-Watering | Y29: 96 | Z29: =D29*I29 -> 4300
A30: CAS 1P | B30: Cup and Saucer (HB) | C30: Black | D30: 5 | E30: =D30*2.8 -> 14 | F30: 45 | G30: =F30-E30 -> 31 | H30: =(CleanedDataset!$F58-CleanedDataset!$E58)/CleanedDataset!$F58 -> 0.68 | I30: 787 | J30: =I30*F30-I30*E30 -> 24397 | K30: 478 | L30: =K30*F30-I30*E30 -> 10492 | M30: 1235 | N30: =M30*F30-M30*E30 -> 38285 | O30: 1450 | P30: =O30*F30-O30*E30 -> 44950 | Q30: 1728 | R30: =Q30*F30-Q30*E30 -> 53568 | S30: 1182 | T30: =S30*F30-S30*E30 -> 36642 | U30: 999 | V30: =U30*F30-U30*E30 -> 30969 | W30: =SUM(S30,Q30,O30,M30,K30,I30) -> 6860 | X30: Self-Watering | Y30: 97 | Z30: =D30*I30 -> 3935
A31: CHB 1P | B31: Conventional Hanging Basket | C31: Cherry | D31: 5 | E31: =D31*3 -> 15 | F31: 45 | G31: =F31-E31 -> 30 | H31: =(CleanedDataset!$F75-CleanedDataset!$E75)/CleanedDataset!$F75 -> 0.79466667 | I31: 28 | J31: =I31*F31-I31*E31 -> 840 | K31: 5 | L31: =K31*F31-I31*E31 -> -195 | M31: 0 | N31: =M31*F31-M31*E31 -> 0 | O31: 0 | P31: =O31*F31-O31*E31 -> 0 | Q31: 0 | R31: =Q31*F31-Q31*E31 -> 0 | S31: 0 | T31: =S31*F31-S31*E31 -> 0 | U31: 0 | V31: =U31*F31-U31*E31 -> 0 | W31: =SUM(S31,Q31,O31,M31,K31,I31) -> 33 | X31: Self-Watering | Y31: 90 | Z31: =D31*I31 -> 140
A32: CHB 1P | B32: Conventional Hanging Basket | C32: Standard Green | D32: 5 | E32: =D32*3 -> 15 | F32: 45 | G32: =F32-E32 -> 30 | H32: =(CleanedDataset!$F158-CleanedDataset!$E158)/CleanedDataset!$F158 -> 0.2 | I32: 342 | J32: =I32*F32-I32*E32 -> 10260 | K32: 280 | L32: =K32*F32-I32*E32 -> 7470 | M32: 133 | N32: =M32*F32-M32*E32 -> 3990 | O32: 200 | P32: =O32*F32-O32*E32 -> 6000 | Q32: 187 | R32: =Q32*F32-Q32*E32 -> 5610 | S32: 850 | T32: =S32*F32-S32*E32 -> 25500 | U32: 345 | V32: =U32*F32-U32*E32 -> 10350 | W32: =SUM(S32,Q32,O32,M32,K32,I32) -> 1992 | X32: Self-Watering | Y32: 94 | Z32: =D32*I32 -> 1710
A33: CHB 1P | B33: Conventional Hanging Basket | C33: Black | D33: 5 | E33: =D33*2.8 -> 14 | F33: 35 | G33: =F33-E33 -> 21 | H33: =(CleanedDataset!$F55-CleanedDataset!$E55)/CleanedDataset!$F55 -> 0.67919799 | I33: 527 | J33: =I33*F33-I33*E33 -> 11067 | K33: 203 | L33: =K33*F33-I33*E33 -> -273 | M33: 395 | N33: =M33*F33-M33*E33 -> 8295 | O33: 499 | P33: =O33*F33-O33*E33 -> 10479 | Q33: 915 | R33: =Q33*F33-Q33*E33 -> 19215 | S33: 230 | T33: =S33*F33-S33*E33 -> 4830 | U33: 532 | V33: =U33*F33-U33*E33 -> 11172 | W33: =SUM(S33,Q33,O33,M33,K33,I33) -> 2769 | X33: Self-Watering | Y33: 91 | Z33: =D33*I33 -> 2635
A34: CHB 2P | B34: Conventional Hanging Basket | C34: Cherry | D34: 5 | E34: =D34*3 -> 15 | F34: 66 | G34: =F34-E34 -> 51 | H34: =(CleanedDataset!$F65-CleanedDataset!$E65)/CleanedDataset!$F65 -> 0.77846154 | I34: 0 | J34: =I34*F34-I34*E34 -> 0 | K34: 5 | L34: =K34*F34-I34*E34 -> 330 | M34: 0 | N34: =M34*F34-M34*E34 -> 0 | O34: 0 | P34: =O34*F34-O34*E34 -> 0 | Q34: 0 | R34: =Q34*F34-Q34*E34 -> 0 | S34: 0 | T34: =S34*F34-S34*E34 -> 0 | U34: 0 | V34: =U34*F34-U34*E34 -> 0 | W34: =SUM(S34,Q34,O34,M34,K34,I34) -> 5 | X34: Self-Watering | Y34: 91 | Z34: =D34*I34 -> 0
A35: CHB 2P | B35: Conventional Hanging Basket | C35: Orange | D35: 5 | E35: =D35*3 -> 15 | F35: 66 | G35: =F35-E35 -> 51 | H35: =(CleanedDataset!$F101-CleanedDataset!$E101)/CleanedDataset!$F101 -> 0.1 | I35: 1 | J35: =I35*F35-I35*E35 -> 51 | K35: 0 | L35: =K35*F35-I35*E35 -> -15 | M35: 0 | N35: =M35*F35-M35*E35 -> 0 | O35: 0 | P35: =O35*F35-O35*E35 -> 0 | Q35: 0 | R35: =Q35*F35-Q35*E35 -> 0 | S35: 0 | T35: =S35*F35-S35*E35 -> 0 | U35: 0 | V35: =U35*F35-U35*E35 -> 0 | W35: =SUM(S35,Q35,O35,M35,K35,I35) -> 1 | X35: Self-Watering | Y35: 98 | Z35: =D35*I35 -> 5
A36: CHB 2P | B36: Conventional Hanging Basket | C36: Standard Green | D36: 5 | E36: =D36*3 -> 15 | F36: 66 | G36: =F36-E36 -> 51 | H36: =(CleanedDataset!$F150-CleanedDataset!$E150)/CleanedDataset!$F150 -> 0.58222222 | I36: 87 | J36: =I36*F36-I36*E36 -> 4437 | K36: 65 | L36: =K36*F36-I36*E36 -> 2985 | M36: 50 | N36: =M36*F36-M36*E36 -> 2550 | O36: 67 | P36: =O36*F36-O36*E36 -> 3417 | Q36: 50 | R36: =Q36*F36-Q36*E36 -> 2550 | S36: 35 | T36: =S36*F36-S36*E36 -> 1785 | U36: 55 | V36: =U36*F36-U36*E36 -> 2805 | W36: =SUM(S36,Q36,O36,M36,K36,I36) -> 354 | X36: Self-Watering | Y36: 91 | Z36: =D36*I36 -> 435
A37: CHB 2P | B37: Conventional Hanging Basket | C37: Black | D37: 5 | E37: =D37*2.8 -> 14 | F37: 56 | G37: =F37-E37 -> 42 | H37: =(CleanedDataset!$F35-CleanedDataset!$E35)/CleanedDataset!$F35 -> 0.77272727 | I37: 61 | J37: =I37*F37-I37*E37 -> 2562 | K37: 97 | L37: =K37*F37-I37*E37 -> 4578 | M37: 29 | N37: =M37*F37-M37*E37 -> 1218 | O37: 91 | P37: =O37*F37-O37*E37 -> 3822 | Q37: 62 | R37: =Q37*F37-Q37*E37 -> 2604 | S37: 419 | T37: =S37*F37-S37*E37 -> 17598 | U37: 37 | V37: =U37*F37-U37*E37 -> 1554 | W37: =SUM(S37,Q37,O37,M37,K37,I37) -> 759 | X37: Self-Watering | Y37: 96 | Z37: =D37*I37 -> 305
A38: CHK 1P | B38: Chick bin | C38: Black | D38: 30 | E38: =D38*2.8 -> 84 | F38: 250 | G38: =F38-E38 -> 166 | H38: =(CleanedDataset!$F17-CleanedDataset!$E17)/CleanedDataset!$F17 -> 0.70285714 | I38: 15 | J38: =I38*F38-I38*E38 -> 2490 | K38: 17 | L38: =K38*F38-I38*E38 -> 2990 | M38: 15 | N38: =M38*F38-M38*E38 -> 2490 | O38: 20 | P38: =O38*F38-O38*E38 -> 3320 | Q38: 35 | R38: =Q38*F38-Q38*E38 -> 5810 | S38: 24 | T38: =S38*F38-S38*E38 -> 3984 | U38: 15 | V38: =U38*F38-U38*E38 -> 2490 | W38: =SUM(S38,Q38,O38,M38,K38,I38) -> 126 | X38: Bins | Y38: 90 | Z38: =D38*I38 -> 450
A39: CNS 1P | B39: Cup and Saucer on pole | C39: Light Green | D39: 7 | E39: =D39*3 -> 21 | F39: 55 | G39: =F39-E39 -> 34 | H39: =(CleanedDataset!$F87-CleanedDataset!$E87)/CleanedDataset!$F87 -> 0.49152542 | I39: 23 | J39: =I39*F39-I39*E39 -> 782 | K39: 15 | L39: =K39*F39-I39*E39 -> 342 | M39: 0 | N39: =M39*F39-M39*E39 -> 0 | O39: 0 | P39: =O39*F39-O39*E39 -> 0 | Q39: 0 | R39: =Q39*F39-Q39*E39 -> 0 | S39: 0 | T39: =S39*F39-S39*E39 -> 0 | U39: 0 | V39: =U39*F39-U39*E39 -> 0 | W39: =SUM(S39,Q39,O39,M39,K39,I39) -> 38 | X39: Self-Watering | Y39: 90 | Z39: =D39*I39 -> 161
A40: CNS 1P | B40: Cup and Saucer on pole | C40: Standard Green | D40: 7 | E40: =D40*3 -> 21 | F40: 55 | G40: =F40-E40 -> 34 | H40: =(CleanedDataset!$F169-CleanedDataset!$E169)/CleanedDataset!$F169 -> 0.49090909 | I40: 1578 | J40: =I40*F40-I40*E40 -> 53652 | K40: 1450 | L40: =K40*F40-I40*E40 -> 46612 | M40: 1135 | N40: =M40*F40-M40*E40 -> 38590 | O40: 957 | P40: =O40*F40-O40*E40 -> 32538 | Q40: 2300 | R40: =Q40*F40-Q40*E40 -> 78200 | S40: 2780 | T40: =S40*F40-S40*E40 -> 94520 | U40: 2800 | V40: =U40*F40-U40*E40 -> 95200 | W40: =SUM(S40,Q40,O40,M40,K40,I40) -> 10200 | X40: Self-Watering | Y40: 95 | Z40: =D40*I40 -> 11046
...

Sheet Sheet19
A1: Product | B1: Cost | C1: Selling Price | D1: Ideal Price | E1: Profit | F1: Profit Margin | G1: Sales in 2012 | H1: Margin = cost * Profit Margin % | J1: Ideal Price = Product Cost + Margin
A2: BRL 0P | B2: 45 | C2: 75 | D2: =B2+H2 -> 82 | E2: 30 | F2: 0.82222222 | G2: 496 | H2: =B2*F2 -> 37
A3: BBU 1P | B3: 16.8 | C3: 40 | D3: =B3+H3 -> 28.540235 | E3: 23.2 | F3: 0.69882353 | G3: 405 | H3: =B3*F3 -> 11.740235
A4: BBU 1P | B4: 19.2 | C4: 55 | D4: =B4+H4 -> 32.522449 | E4: 35.8 | F4: 0.69387755 | G4: 530 | H4: =B4*F4 -> 13.322449
A5: BBU 1P | B5: 18 | C5: 50 | D5: =B5+H5 -> 26.795455 | E5: 32 | F5: 0.48863636 | G5: 450 | H5: =B5*F5 -> 8.7954545
A6: BBU 1PL | B6: 9.8 | C6: 25 | D6: =B6+H6 -> 17.313333 | E6: 15.2 | F6: 0.76666667 | G6: 604 | H6: =B6*F6 -> 7.5133333
A7: BBU 1PL | B7: 10.5 | C7: 35 | D7: =B7+H7 -> 14.986364 | E7: 24.5 | F7: 0.42727273 | G7: 1350 | H7: =B7*F7 -> 4.4863636
A8: BHV 5P | B8: 154 | C8: 530 | D8: =B8+H8 -> 249.2 | E8: 376 | F8: 0.61818182 | G8: 58 | H8: =B8*F8 -> 95.2
A9: BHV 5P | B9: 176 | C9: 615 | D9: =B9+H9 -> 242.48889 | E9: 439 | F9: 0.37777778 | G9: 57 | H9: =B9*F9 -> 66.488889
A10: BHV 5P | B10: 176 | C10: 600 | D10: =B10+H10 -> 279.01176 | E10: 424 | F10: 0.58529412 | G10: 35 | H10: =B10*F10 -> 103.01176
A11: BHV 5P | B11: 165 | C11: 600 | D11: =B11+H11 -> 123.31579 | E11: 435 | F11: -0.25263158 | G11: 66 | H11: =B11*F11 -> -41.684211
A12: BHV 6P | B12: 182 | C12: 584 | D12: =B12+H12 -> 284.72889 | E12: 402 | F12: 0.56444444 | G12: 51 | H12: =B12*F12 -> 102.72889
A13: BHV 6P | B13: 208 | C13: 700 | D13: =B13+H13 -> 353.6 | E13: 492 | F13: 0.7 | G13: 5 | H13: =B13*F13 -> 145.6
... A203: RCY 1P | B203: 84 | C203: 300 | D203: =B203+H203 -> 140 | E203: 216 | F203: 0.66666667 | G203: 25 | H203: =B203*F203 -> 56

Sheet Sheet18
A3: Row Labels | B3: Average of Profit Margin | C3: Sum of Sales
A4: Light Green | B4: 0.72347403 | C4: 59
A5: Moss Stone | B5: 0.70285714 | C5: 5
A6: Standard Green | B6: 0.69263234 | C6: 51299
A7: Orange | B7: 0.67651515 | C7: 27
A8: Cherry | B8: 0.67585009 | C8: 87
A9: Pink Granite | B9: 0.66633687 | C9: 1658
A10: Black | B10: 0.62360726 | C10: 88453
A11: Guerney Granite | B11: 0.60305699 | C11: 466
A12: Sky Blue | B12: 0.57783879 | C12: 226
A13: Dark Sandstone | B13: 0.552 | C13: 39
A14: Millstone Gritt | B14: 0.552 | C14: 23
A15: Light Sandstone | B15: 0.51901875 | C15: 81
... A19: Grand Total | B19: 0.59640618 | C19: 151180

Sheet Sheet16
A1: Product Family | B1: Colour | C1: Profit Margin | D1: Total Nr of Sales | E1: Selling_Price_Pound | F1: Performance Score (Number of Sales * Profit Margin) / Selling Price) | K1: Product Family | L1: Column1 | M1: Colour | N1: Sales | O1: Profit Margin
A2: Self-Watering | B2: Black | C2: 0.49090909 | D2: 40 | E2: 220 | F2: =(D2*C2)/E2 -> 0.089256198 | K2: Self-Watering | M2: Black | N2: 40 | O2: 0.49090909
A3: Self-Watering | B3: Black | C3: 0.70984456 | D3: 12 | E3: 579 | F3: =(D3*C3)/E3 -> 0.014711804 | K3: Self-Watering | M3: Black | N3: 12 | O3: 0.70984456
A4: Self-Watering | B4: Black | C4: 0.58222222 | D4: 1 | E4: 315 | F4: =(D4*C4)/E4 -> 0.0018483245 | K4: Self-Watering | M4: Black | N4: 1 | O4: 0.58222222
A5: Planterware | B5: Black | C5: -0.30666667 | D5: 0 | E5: 30 | F5: =(D5*C5)/E5 -> 0 | K5: Planterware | M5: Black | N5: 0 | O5: -0.30666667
A6: Planterware | B6: Black | C6: -0.25263158 | D6: 0 | E6: 38 | F6: =(D6*C6)/E6 -> 0 | K6: Planterware | M6: Black | N6: 0 | O6: -0.25263158
A7: Self-Watering | B7: Black | C7: 0.61294118 | D7: 74 | E7: 340 | F7: =(D7*C7)/E7 -> 0.13340484 | K7: Self-Watering | M7: Black | N7: 74 | O7: 0.61294118
A8: Self-Watering | B8: Black | C8: 0.552 | D8: 59 | E8: 250 | F8: =(D8*C8)/E8 -> 0.130272 | K8: Self-Watering | M8: Black | N8: 59 | O8: 0.552
A9: Bins | B9: Black | C9: 0.86 | D9: 23 | E9: 100 | F9: =(D9*C9)/E9 -> 0.1978 | K9: Bins | M9: Black | N9: 23 | O9: 0.86
A10: Self-Watering | B10: Black | C10: 0.65777778 | D10: 21 | E10: 450 | F10: =(D10*C10)/E10 -> 0.030696296 | K10: Self-Watering | M10: Black | N10: 21 | O10: 0.65777778
A11: Self-Watering | B11: Black | C11: 0.72 | D11: 115 | E11: 60 | F11: =(D11*C11)/E11 -> 1.38 | K11: Self-Watering | M11: Black | N11: 115 | O11: 0.72
A12: Bins | B12: Black | C12: 0.83666667 | D12: 10 | E12: 120 | F12: =(D12*C12)/E12 -> 0.069722222 | K12: Bins | M12: Black | N12: 10 | O12: 0.83666667
A13: Bins | B13: Black | C13: 0.7 | D13: 69 | E13: 280 | F13: =(D13*C13)/E13 -> 0.1725 | K13: Bins | M13: Black | N13: 69 | O13: 0.7
... A203: Self-Watering | B203: White Marble | C203: 0.37777778 | D203: 5 | E203: 180 | F203: =(D203*C203)/E203 -> 0.010493827 | K203: Self-Watering | M203: White Marble | N203: 5 | O203: 0.37777778

Sheet Sheet11
A1: Product Family | B1: Bins | C1: Forecast(Bins) | D1: Lower Confidence Bound(Bins) | E1: Upper Confidence Bound(Bins)
A2: 2006 | B2: 1230
A3: 2007 | B3: 1453
A4: 2008 | B4: 1674
A5: 2009 | B5: 1328
A6: 2010 | B6: 2543
A7: 2011 | B7: 2081
A8: 2012 | B8: 2048 | C8: 2048 | D8: 2048 | E8: 2048
A9: 2013 | C9: =_xlfn.FORECAST.ETS(A9,$B$2:$B$8,$A$2:$A$8,1,1) -> 2376.6128 | D9: =C9-_xlfn.FORECAST.ETS.CONFINT(A9,$B$2:$B$8,$A$2:$A$8,0.95,1,1) -> 1786.4394 | E9: =C9+_xlfn.FORECAST.ETS.CONFINT(A9,$B$2:$B$8,$A$2:$A$8,0.95,1,1) -> 2966.7861
A10: 2014 | C10: =_xlfn.FORECAST.ETS(A10,$B$2:$B$8,$A$2:$A$8,1,1) -> 2540.4576 | D10: =C10-_xlfn.FORECAST.ETS.CONFINT(A10,$B$2:$B$8,$A$2:$A$8,0.95,1,1) -> 1950.2817 | E10: =C10+_xlfn.FORECAST.ETS.CONFINT(A10,$B$2:$B$8,$A$2:$A$8,0.95,1,1) -> 3130.6336
A11: 2015 | C11: =_xlfn.FORECAST.ETS(A11,$B$2:$B$8,$A$2:$A$8,1,1) -> 2704.3025 | D11: =C11-_xlfn.FORECAST.ETS.CONFINT(A11,$B$2:$B$8,$A$2:$A$8,0.95,1,1) -> 2114.1218 | E11: =C11+_xlfn.FORECAST.ETS.CONFINT(A11,$B$2:$B$8,$A$2:$A$8,0.95,1,1) -> 3294.4832
A12: 2016 | C12: =_xlfn.FORECAST.ETS(A12,$B$2:$B$8,$A$2:$A$8,1,1) -> 2868.1474 | D12: =C12-_xlfn.FORECAST.ETS.CONFINT(A12,$B$2:$B$8,$A$2:$A$8,0.95,1,1) -> 2277.9593 | E12: =C12+_xlfn.FORECAST.ETS.CONFINT(A12,$B$2:$B$8,$A$2:$A$8,0.95,1,1) -> 3458.3355
A13: 2017 | C13: =_xlfn.FORECAST.ETS(A13,$B$2:$B$8,$A$2:$A$8,1,1) -> 3031.9923 | D13: =C13-_xlfn.FORECAST.ETS.CONFINT(A13,$B$2:$B$8,$A$2:$A$8,0.95,1,1) -> 2441.7936 | E13: =C13+_xlfn.FORECAST.ETS.CONFINT(A13,$B$2:$B$8,$A$2:$A$8,0.95,1,1) -> 3622.191

Sheet All
A1: Product | B1: Description | C1: Colour | D1: Powder weight (kg) | E1: Selling Price £ | F1: 2012 | G1: 2011 | H1: 2010 | I1: 2009 | J1: 2008 | K1: 2007 | L1: 2006 | M1: Product Family | N1: Due Date Performance/%
A2: CAS 0P | B2: Cup and Saucer | C2: Black | D2: 7 | E2: 30 | F2: 2132 | G2: 2648 | H2: 2712 | I2: 1775 | J2: 2302 | K2: 2250 | L2: 2532 | M2: Self-Watering | N2: 91
A3: CAS 0P | B3: Cup and Saucer | C3: Standard Green | D3: 7 | E3: 40 | F3: 1300 | G3: 1250 | H3: 800 | I3: 750 | J3: 1200 | K3: 2050 | L3: 1980 | M3: Self-Watering | N3: 97
A4: CAS 0P | B4: Cup and Saucer | C4: Orange | D4: 7 | E4: 40 | F4: 6 | G4: 15 | M4: Self-Watering | N4: 94
A5: CAS 0P | B5: Cup and Saucer | C5: Sky Blue | D5: 7 | E5: 40 | F5: 135 | G5: 46 | M5: Self-Watering | N5: 95
A6: BBU 1P | B6: Barrier Basket | C6: Black | D6: 6 | E6: 40 | F6: 405 | G6: 534 | H6: 987 | I6: 1917 | J6: 1047 | K6: 326 | L6: 857 | M6: Self-Watering | N6: 92
A7: BBU 1P | B7: Barrier Basket | C7: Standard Green | D7: 6 | E7: 50 | F7: 450 | G7: 300 | H7: 230 | I7: 200 | J7: 225 | K7: 705 | L7: 680 | M7: Self-Watering | N7: 92
A8: BBU 1P | B8: Barrier Basket | C8: Pink Granite | D8: 6 | E8: 55 | F8: 530 | G8: 135 | M8: Self-Watering | N8: 90
A9: OCT 0P | B9: Octagonal fountain | C9: Black | D9: 35 | E9: 185 | F9: 112 | G9: 98 | H9: 92 | I9: 235 | J9: 176 | K9: 88 | L9: 28 | M9: Self-Watering | N9: 97
A10: OCT 0P | B10: Octagonal fountain | C10: Standard Green | D10: 35 | E10: 250 | F10: 230 | G10: 187 | H10: 135 | I10: 87 | J10: 53 | K10: 235 | L10: 200 | M10: Self-Watering | N10: 96
A11: OCT 0P | B11: Octagonal fountain | C11: Dark Sandstone | D11: 35 | E11: 250 | F11: 26 | G11: 13 | M11: Self-Watering | N11: 95
A12: OCT 0P | B12: Octagonal fountain | C12: Guerney Granite | D12: 35 | E12: 250 | F12: 135 | G12: 78 | M12: Self-Watering | N12: 95
A13: OCT 0P | B13: Octagonal fountain | C13: Millstone Gritt | D13: 35 | E13: 250 | F13: 15 | G13: 8 | M13: Self-Watering | N13: 97
A14: OCT 0P | B14: Octagonal fountain | C14: Pink Granite | D14: 35 | E14: 250 | F14: 76 | G14: 55 | M14: Self-Watering | N14: 95
A15: CNS 1P | B15: Cup and Saucer on pole | C15: Black | D15: 7 | E15: 45 | F15: 1064 | G15: 1153 | H15: 1979 | I15: 2901 | J15: 2434 | K15: 1693 | L15: 1311 | M15: Self-Watering | N15: 94
A16: CNS 1P | B16: Cup and Saucer on pole | C16: Standard Green | D16: 7 | E16: 55 | F16: 1578 | G16: 1450 | H16: 1135 | I16: 957 | J16: 2300 | K16: 2780 | L16: 2800 | M16: Self-Watering | N16: 95
A17: CNS 1P | B17: Cup and Saucer on pole | C17: Light Green | D17: 7 | E17: 55 | F17: 23 | G17: 15 | M17: Self-Watering | N17: 90
A18: BRL 0P | B18: Barrel | C18: Brown | D18: 15 | E18: 75 | F18: 496 | G18: 557 | M18: Self-Watering | N18: 91
A19: BHV 5P | B19: Bee hive fountain (5) | C19: Black | D19: 55 | E19: 530 | F19: 58 | G19: 75 | H19: 39 | I19: 16 | J19: 21 | K19: 60 | L19: 64 | M19: Self-Watering | N19: 100
A20: BHV 5P | B20: Bee hive fountain (5) | C20: Standard Green | D20: 55 | E20: 600 | F20: 66 | G20: 35 | H20: 12 | I20: 15 | J20: 33 | K20: 50 | L20: 45 | M20: Self-Watering | N20: 94
A21: BHV 5P | B21: Bee hive fountain (5) | C21: Pink Granite | D21: 55 | E21: 600 | F21: 35 | G21: 14 | M21: Self-Watering | N21: 90
A22: BHV 5P | B22: Bee hive fountain (5) | C22: Guerney Granite | D22: 55 | E22: 615 | F22: 57 | G22: 35 | M22: Self-Watering | N22: 93
A23: BHV 6P | B23: Bee hive fountain (6) | C23: Black | D23: 65 | E23: 584 | F23: 51 | G23: 78 | H23: 193 | I23: 0 | J23: 0 | K23: 0 | L23: 0 | M23: Self-Watering | N23: 94
A24: BHV 6P | B24: Bee hive fountain (6) | C24: Standard Green | D24: 65 | E24: 650 | F24: 158 | G24: 113 | H24: 250 | M24: Self-Watering | N24: 97
A25: BHV 6P | B25: Bee hive fountain (6) | C25: Light Green | D25: 65 | E25: 650 | F25: 3 | M25: Self-Watering | N25: 98
A26: BHV 6P | B26: Bee hive fountain (6) | C26: Moss Stone | D26: 65 | E26: 700 | G26: 5 | M26: Self-Watering | N26: 98
A27: BHV 6P | B27: Bee hive fountain (6) | C27: Guerney Granite | D27: 65 | E27: 700 | F27: 5 | M27: Self-Watering | N27: 99
A28: BHV 6P | B28: Bee hive fountain (6) | C28: Pink Granite | D28: 65 | E28: 700 | F28: 53 | G28: 28 | M28: Self-Watering | N28: 93
A29: UTP 2P | B29: Half basket up the pole | C29: Black | D29: 5 | E29: 65 | F29: 728 | G29: 871 | H29: 913 | I29: 1800 | J29: 1315 | K29: 577 | L29: 573 | M29: Self-Watering | N29: 93
A30: UTP 2P | B30: Half basket up the pole | C30: Standard Green | D30: 5 | E30: 70 | F30: 890 | G30: 765 | H30: 521 | I30: 220 | J30: 349 | K30: 1385 | L30: 1290 | M30: Self-Watering | N30: 93
A31: UTP 2P | B31: Half basket up the pole | C31: Sky Blue | D31: 5 | E31: 70 | F31: 23 | G31: 5 | M31: Self-Watering | N31: 93
A32: UTP 2P | B32: Half basket up the pole | C32: Light Green | D32: 5 | E32: 70 | F32: 15 | M32: Self-Watering | N32: 99
A33: CAS 1P | B33: Cup and Saucer (HB) | C33: Black | D33: 5 | E33: 45 | F33: 787 | G33: 478 | H33: 1235 | I33: 1450 | J33: 1728 | K33: 1182 | L33: 999 | M33: Self-Watering | N33: 97
A34: CAS 1P | B34: Cup and Saucer (HB) | C34: Standard Green | D34: 5 | E34: 50 | F34: 860 | G34: 744 | H34: 343 | I34: 320 | J34: 287 | K34: 680 | L34: 623 | M34: Self-Watering | N34: 96
A35: CAS 1P | B35: Cup and Saucer (HB) | C35: Light Sandstone | D35: 5 | E35: 60 | F35: 23 | G35: 35 | M35: Self-Watering | N35: 95
A36: MSP 0P | B36: Meter sq planter | C36: Black | D36: 35 | E36: 135 | F36: 116 | G36: 164 | H36: 319 | I36: 251 | J36: 207 | K36: 182 | L36: 54 | M36: Self-Watering | N36: 96
A37: MSP 0P | B37: Meter sq planter | C37: Pink Granite | D37: 35 | E37: 180 | G37: 89 | M37: Self-Watering | N37: 92
A38: MSP 0P | B38: Meter sq planter | C38: Light Sandstone | D38: 35 | E38: 180 | F38: 5 | M38: Self-Watering | N38: 98
A39: MSP 0P | B39: Meter sq planter | C39: White Marble | D39: 35 | E39: 180 | F39: 5 | M39: Self-Watering | N39: 97
A40: UTP 1P | B40: Half basket up the pole | C40: Black | D40: 4 | E40: 45 | F40: 962 | G40: 1465 | H40: 1334 | I40: 2383 | J40: 1525 | K40: 1582 | L40: 1539 | M40: Self-Watering | N40: 100
...

Sheet Information
B2: The company produces own range of plastic planters and bins. There are two product families for planters: Self-watering and Planterware.
B3: Self-watering planters are planters designed with self-watering feature. This feature consists of a built-in water reservoir and capillary mechanisms.
B4: In order to increase competitiveness, the company has increased the colours offered. Majority of the colours were only introduced from year 2011 onwards
B5: except Black and Standard Green colors. Make-to-Order business model is adopted.
B7: Standard Industry Lead Time : 2 Weeks for Planters, 3 Weeks for Bins
B22: Powder Cost £/kg | F22: Typical Demand Distribution %
B23: Colour | C23: Cost | F23: Month | G23: Demand of Planters | H23: Demand of Bins
B24: White | C24: 3 | F24: Jan | G24: 3 | H24: 10
B25: Black | C25: 2.8 | F25: Feb | G25: 8 | H25: 11
B26: Biscuit | C26: 3 | F26: Mac | G26: 13 | H26: 8
B27: Terracotta | C27: 3 | F27: April | G27: 18 | H27: 4
B28: Cherry | C28: 3 | F28: May | G28: 18 | H28: 2
B29: Orange | C29: 3 | F29: June | G29: 15 | H29: 3
B30: Sky Blue | C30: 3 | F30: July | G30: 10 | H30: 7
B31: Navy Blue | C31: 3 | F31: August | G31: 8 | H31: 7
B32: Light Green | C32: 3 | F32: Sept | G32: 3 | H32: 8
B33: Standard Green | C33: 3 | F33: Oct | G33: 2 | H33: 13
B34: White Marble | C34: 3.2 | F34: Nov | G34: 1 | H34: 15
B35: Pink Granite | C35: 3.2 | F35: Dec | G35: 1 | H35: 12
B36: Tudor Brown Mottle | C36: 3 | F36: Total | G36: =SUM(G24:G35) -> 100 | H36: =SUM(H24:H35) -> 100
B37: Moss Stone | C37: 3.2
B38: Light Sandstone | C38: 3.2
B39: Dark Standstone | C39: 3.2
B40: Guernsey Granite | C40: 3.2
B41: Millstone Gritt | C41: 3.2
B42: Brown | C42: 3
B45: Transaction cost/order to supplier: £50
B47: Distance between Powder Supplier and the company is assumed to be 500 miles
B48: Delivery Cost/20 ft Container: £750 (for 500 miles)
B49: Capacity/20 ft Container: 10 pallets
B50: Delivery Cost/Pallet (500 miles): £100
B51: Minimum order quantity for powder is ONE pallet per colour; Each pallet is 500kg
B53: Warehouse: | C53: The company has their own warehouse and assumed to be always available (for both Raw Material and Finished Goods).
B54: Holding Cost: | C54: 7% of total capital tied up as inventory (Raw Material/Finished Goods)
B56: Product selling price is Ex Works: Delivery method and cost is chosen and paid by customers

Sheet Sheet3
J6: Years | K6: Total Sales | L6: New Colour Sales
J7: 2012 | K7: 29941 | L7: 2428 | M7: 25472 | N7: =SUM(L7:M7) -> 27900
J8: 2011 | K8: 24843 | L8: 1308
J9: 2010 | K9: 22470
J10: 2009 | K10: 23226
J11: 2008 | K11: 24809
J12: 2007 | K12: 25891
J13: 2006 | K13: 24122

Sheet ColorR
A1: Colours | B1: Sales_2012 | C1: Sales_2011
A2: Pink Granite | B2: 885 | C2: 462
A3: Brown | B3: 496 | C3: 557
A4: Terracota | B4: 249 | C4: 56
A5: Cherry | B5: 209 | C5: 0
A6: Sky Blue | B6: 295 | C6: 46
A7: Guerney Granite | B7: 140 | C7: 62
A8: Dark Sandstone | B8: 53 | C8: 21
A9: Light Green | B9: 38 | C9: 41
A10: Light Sandstone | B10: 36 | C10: 30
A11: Millstone Gritt | B11: 15 | C11: 8
A12: Orange | B12: 7 | C12: 20
A13: White Marble | B13: 5 | C13: 0
A14: Moss Stone | B14: 0 | C14: 5

Sheet All_Cleaned
A1: Product | B1: Description | C1: Colour | D1: Powder weight (kg) | E1: Selling Price £ | F1: Salesin_2012 | G1: Salesin_2011 | H1: Salesin_2010 | I1: Salesin_2009 | J1: Salesin_2008 | K1: Salesin_2007 | L1: Salesin_2006 | M1: Product Family | N1: Due Date Performance/% | O1: Powder Cost | P1: Cost | Q1: Net Profit | R1: Profit Margin %
A2: BHV 6P | B2: Bee hive fountain (6) | C2: Guerney Granite | D2: 65 | E2: 700 | F2: 5 | G2: 0 | H2: 0 | I2: 0 | J2: 0 | K2: 0 | L2: 0 | M2: Self-Watering | N2: 99 | O2: {=_xlfn.XLOOKUP(C2,Table1[[#All],[Colour]],Table1[[#All],[Cost]],0)} -> 0 | P2: =O2*D2 -> 0 | Q2: =E2-P2 -> 700 | R2: =Q2/E2*100 -> 100
A3: BHV 5P | B3: Bee hive fountain (5) | C3: Guerney Granite | D3: 55 | E3: 615 | F3: 57 | G3: 35 | H3: 0 | I3: 0 | J3: 0 | K3: 0 | L3: 0 | M3: Self-Watering | N3: 93 | O3: {=_xlfn.XLOOKUP(C3,Table1[[#All],[Colour]],Table1[[#All],[Cost]],0)} -> 0 | P3: =O3*D3 -> 0 | Q3: =E3-P3 -> 615 | R3: =Q3/E3*100 -> 100
A4: MSP 3P | B4: Meter sq planter (3) | C4: Guerney Granite | D4: 55 | E4: 510 | F4: 53 | G4: 21 | H4: 0 | I4: 0 | J4: 0 | K4: 0 | L4: 0 | M4: Self-Watering | N4: 99 | O4: {=_xlfn.XLOOKUP(C4,Table1[[#All],[Colour]],Table1[[#All],[Cost]],0)} -> 0 | P4: =O4*D4 -> 0 | Q4: =E4-P4 -> 510 | R4: =Q4/E4*100 -> 100
A5: BHV 6P | B5: Bee hive fountain (6) | C5: Moss Stone | D5: 65 | E5: 700 | F5: 0 | G5: 5 | H5: 0 | I5: 0 | J5: 0 | K5: 0 | L5: 0 | M5: Self-Watering | N5: 98 | O5: {=_xlfn.XLOOKUP(C5,Table1[[#All],[Colour]],Table1[[#All],[Cost]],0)} -> 3.2 | P5: =O5*D5 -> 208 | Q5: =E5-P5 -> 492 | R5: =Q5/E5*100 -> 70.285714
A6: BHV 6P | B6: Bee hive fountain (6) | C6: Pink Granite | D6: 65 | E6: 700 | F6: 53 | G6: 28 | H6: 0 | I6: 0 | J6: 0 | K6: 0 | L6: 0 | M6: Self-Watering | N6: 93 | O6: {=_xlfn.XLOOKUP(C6,Table1[[#All],[Colour]],Table1[[#All],[Cost]],0)} -> 3.2 | P6: =O6*D6 -> 208 | Q6: =E6-P6 -> 492 | R6: =Q6/E6*100 -> 70.285714
A7: MSP 4P | B7: Meter sq planter (4) | C7: Pink Granite | D7: 60 | E7: 650 | F7: 3 | G7: 0 | H7: 0 | I7: 0 | J7: 0 | K7: 0 | L7: 0 | M7: Self-Watering | N7: 92 | O7: {=_xlfn.XLOOKUP(C7,Table1[[#All],[Colour]],Table1[[#All],[Cost]],0)} -> 3.2 | P7: =O7*D7 -> 192 | Q7: =E7-P7 -> 458 | R7: =Q7/E7*100 -> 70.461538
A8: MSP 4P | B8: Meter sq planter (4) | C8: Light Sandstone | D8: 60 | E8: 650 | F8: 5 | G8: 0 | H8: 0 | I8: 0 | J8: 0 | K8: 0 | L8: 0 | M8: Self-Watering | N8: 99 | O8: {=_xlfn.XLOOKUP(C8,Table1[[#All],[Colour]],Table1[[#All],[Cost]],0)} -> 3.2 | P8: =O8*D8 -> 192 | Q8: =E8-P8 -> 458 | R8: =Q8/E8*100 -> 70.461538
A9: BHV 6P | B9: Bee hive fountain (6) | C9: Standard Green | D9: 65 | E9: 650 | F9: 158 | G9: 113 | H9: 250 | I9: 0 | J9: 0 | K9: 0 | L9: 0 | M9: Self-Watering | N9: 97 | O9: {=_xlfn.XLOOKUP(C9,Table1[[#All],[Colour]],Table1[[#All],[Cost]],0)} -> 3 | P9: =O9*D9 -> 195 | Q9: =E9-P9 -> 455 | R9: =Q9/E9*100 -> 70
A10: BHV 6P | B10: Bee hive fountain (6) | C10: Light Green | D10: 65 | E10: 650 | F10: 3 | G10: 0 | H10: 0 | I10: 0 | J10: 0 | K10: 0 | L10: 0 | M10: Self-Watering | N10: 98 | O10: {=_xlfn.XLOOKUP(C10,Table1[[#All],[Colour]],Table1[[#All],[Cost]],0)} -> 3 | P10: =O10*D10 -> 195 | Q10: =E10-P10 -> 455 | R10: =Q10/E10*100 -> 70
A11: BHV 5P | B11: Bee hive fountain (5) | C11: Standard Green | D11: 55 | E11: 600 | F11: 66 | G11: 35 | H11: 12 | I11: 15 | J11: 33 | K11: 50 | L11: 45 | M11: Self-Watering | N11: 94 | O11: {=_xlfn.XLOOKUP(C11,Table1[[#All],[Colour]],Table1[[#All],[Cost]],0)} -> 3 | P11: =O11*D11 -> 165 | Q11: =E11-P11 -> 435 | R11: =Q11/E11*100 -> 72.5
A12: BHV 5P | B12: Bee hive fountain (5) | C12: Pink Granite | D12: 55 | E12: 600 | F12: 35 | G12: 14 | H12: 0 | I12: 0 | J12: 0 | K12: 0 | L12: 0 | M12: Self-Watering | N12: 90 | O12: {=_xlfn.XLOOKUP(C12,Table1[[#All],[Colour]],Table1[[#All],[Cost]],0)} -> 3.2 | P12: =O12*D12 -> 176 | Q12: =E12-P12 -> 424 | R12: =Q12/E12*100 -> 70.666667
A13: MSP 4P | B13: Meter sq planter (4) | C13: Black | D13: 60 | E13: 579 | F13: 0 | G13: 0 | H13: 0 | I13: 0 | J13: 12 | K13: 0 | L13: 0 | M13: Self-Watering | N13: 96 | O13: {=_xlfn.XLOOKUP(C13,Table1[[#All],[Colour]],Table1[[#All],[Cost]],0)} -> 2.8 | P13: =O13*D13 -> 168 | Q13: =E13-P13 -> 411 | R13: =Q13/E13*100 -> 70.984456
... A155: BRL 0P | B155: Barrel | C155: Brown | D155: 15 | E155: 75 | F155: 496 | G155: 557 | H155: 0 | I155: 0 | J155: 0 | K155: 0 | L155: 0 | M155: Self-Watering | N155: 91 | O155: {=_xlfn.XLOOKUP(C155,Table1[[#All],[Colour]],Table1[[#All],[Cost]],0)} -> 3 | P155: =O155*D155 -> 45 | Q155: =E155-P155 -> 30 | R155: =Q155/E155*100 -> 40
A156: CAS 0P | B156: Cup and Saucer | C156: Black | D156: 7 | E156: 30 | F156: 2132 | G156: 2648 | H156: 2712 | I156: 1775 | J156: 2302 | K156: 2250 | L156: 2532 | M156: Self-Watering | N156: 91 | O156: {=_xlfn.XLOOKUP($C$2,Table1[[#All],[Colour]],Table1[[#All],[Cost]],0)} -> 0 | P156: =O156*D156 -> 0 | Q156: =E156-P156 -> 30 | R156: =Q156/E156*100 -> 100
A157: OVL 0P | B157: Floor standing oval planter | C157: Sky Blue | D157: 30 | E157: 120 | F157: 5 | G157: 0 | H157: 0 | I157: 0 | J157: 0 | K157: 0 | L157: 0 | M157: Self-Watering | N157: 96 | O157: {=_xlfn.XLOOKUP(C157,Table1[[#All],[Colour]],Table1[[#All],[Cost]],0)} -> 3 | P157: =O157*D157 -> 90 | Q157: =E157-P157 -> 30 | R157: =Q157/E157*100 -> 25
A158: OVL 0P | B158: Floor standing oval planter | C158: Cherry | D158: 30 | E158: 120 | F158: 8 | G158: 0 | H158: 0 | I158: 0 | J158: 0 | K158: 0 | L158: 0 | M158: Self-Watering | N158: 97 | O158: {=_xlfn.XLOOKUP(C158,Table1[[#All],[Colour]],Table1[[#All],[Cost]],0)} -> 3 | P158: =O158*D158 -> 90 | Q158: =E158-P158 -> 30 | R158: =Q158/E158*100 -> 25
A159: J-EPV50-T2 | B159: Egg pot vase | C159: Terracotta | D159: 10 | E159: 59 | F159: 194 | G159: 102 | H159: 2 | I159: 0 | J159: 0 | K159: 0 | L159: 0 | M159: Planterware | N159: 96 | O159: {=_xlfn.XLOOKUP(C159,Table1[[#All],[Colour]],Table1[[#All],[Cost]],0)} -> 3 | P159: =O159*D159 -> 30 | Q159: =E159-P159 -> 29 | R159: =Q159/E159*100 -> 49.152542
A160: J-V85-PR | B160: Plain vase | C160: Terracotta | D160: 12 | E160: 65 | F160: 240 | G160: 170 | H160: 15 | I160: 0 | J160: 0 | K160: 0 | L160: 0 | M160: Planterware | N160: 97 | O160: {=_xlfn.XLOOKUP(C160,Table1[[#All],[Colour]],Table1[[#All],[Cost]],0)} -> 3 | P160: =O160*D160 -> 36 | Q160: =E160-P160 -> 29 | R160: =Q160/E160*100 -> 44.615385
A161: SLM 0P | B161: Slim bin | C161: Black | D161: 25 | E161: 99 | F161: 65 | G161: 50 | H161: 95 | I161: 89 | J161: 66 | K161: 30 | L161: 0 | M161: Bins | N161: 93 | O161: {=_xlfn.XLOOKUP(C161,Table1[[#All],[Colour]],Table1[[#All],[Cost]],0)} -> 2.8 | P161: =O161*D161 -> 70 | Q161: =E161-P161 -> 29 | R161: =Q161/E161*100 -> 29.292929
A162: HBB 2P | B162: Half barrier basket | C162: Standard Green | D162: 9 | E162: 55 | F162: 230 | G162: 185 | H162: 74 | I162: 67 | J162: 55 | K162: 80 | L162: 250 | M162: Self-Watering | N162: 90 | O162: {=_xlfn.XLOOKUP(C162,Table1[[#All],[Colour]],Table1[[#All],[Cost]],0)} -> 3 | P162: =O162*D162 -> 27 | Q162: =E162-P162 -> 28 | R162: =Q162/E162*100 -> 50.909091
A163: HBB 2PL | B163: Half barrier basket | C163: Black | D163: 4.5 | E163: 40 | F163: 41 | G163: 68 | H163: 183 | I163: 73 | J163: 79 | K163: 314 | L163: 156 | M163: Self-Watering | N163: 97 | O163: {=_xlfn.XLOOKUP(C163,Table1[[#All],[Colour]],Table1[[#All],[Cost]],0)} -> 2.8 | P163: =O163*D163 -> 12.6 | Q163: =E163-P163 -> 27.4 | R163: =Q163/E163*100 -> 68.5
A164: J-S60 | B164: Square | C164: Terracotta | D164: 8 | E164: 51 | F164: 90 | G164: 35 | H164: 15 | I164: 0 | J164: 0 | K164: 0 | L164: 0 | M164: Planterware | N164: 100 | O164: {=_xlfn.XLOOKUP(C164,Table1[[#All],[Colour]],Table1[[#All],[Cost]],0)} -> 3 | P164: =O164*D164 -> 24 | Q164: =E164-P164 -> 27 | R164: =Q164/E164*100 -> 52.941176
A165: ST 1P | B165: Stipple bin | C165: Black | D165: 10 | E165: 55 | F165: 200 | G165: 233 | H165: 150 | I165: 200 | J165: 148 | K165: 150 | L165: 170 | M165: Bins | N165: 96 | O165: {=_xlfn.XLOOKUP(C165,Table1[[#All],[Colour]],Table1[[#All],[Cost]],0)} -> 2.8 | P165: =O165*D165 -> 28 | Q165: =E165-P165 -> 27 | R165: =Q165/E165*100 -> 49.090909
A166: J-S75-AG | B166: Square | C166: Terracotta | D166: 11 | E166: 60 | F166: 24 | G166: 21 | H166: 3 | I166: 0 | J166: 0 | K166: 0 | L166: 0 | M166: Planterware | N166: 94 | O166: {=_xlfn.XLOOKUP(C166,Table1[[#All],[Colour]],Table1[[#All],[Cost]],0)} -> 3 | P166: =O166*D166 -> 33 | Q166: =E166-P166 -> 27 | R166: =Q166/E166*100 -> 45
